<?xml version="1.0" encoding="utf-8" ?>
<!-- =================================================================================== -->
<!-- |    This document was autogenerated by xacro from src/urdf_rozh_v1/urdf/rozh_model.xacro | -->
<!-- |    EDITING THIS FILE BY HAND IS NOT RECOMMENDED                                 | -->
<!-- =================================================================================== -->
<robot name="rozh_model">
   
    <link name="link1_p1">
        <visual>
			<origin xyz="0 0 0" rpy="0 0 0"/>
            <geometry>
                <mesh filename="package://urdf_rozh_v1/meshes/link1_fin.stl" />
            </geometry>
        </visual>
        <collision>
			<origin xyz="0 0 0" rpy="0 0 0"/>
            <geometry>
                <mesh filename="package://urdf_rozh_v1/meshes/link1_fin.stl" />
            </geometry>
        </collision>        
		<inertial>
			<origin xyz="0 0 0" rpy="0 0 0" />
            <mass value="0.015" />
            <inertia ixx="59.05" iyy="17.03" izz="17.03" ixy="0.0" ixz="0.0" iyz="0.0" />
        </inertial>
    </link>

    <link name="link2_p1">
        <visual>
			<origin xyz="0 0 0" rpy="0 0 0"/>
            <geometry>
                <mesh filename="package://urdf_rozh_v1/meshes/link2_fin.stl" />
            </geometry>
            <!-->material name="gray"/<!-->
        </visual>
        <collision>
			<origin xyz="0 0 0" rpy="0 0 0"/>
            <geometry>
                <mesh filename="package://urdf_rozh_v1/meshes/link2_collision.stl" />
            </geometry>
        </collision>
		<inertial>
			<origin xyz="0 0 0" rpy="0 0 0" />
            <mass value="0.112" />
            <inertia ixx="185.3" iyy="306" izz="3123" ixy="0.0" ixz="0.0" iyz="0.0" />
        </inertial>
    </link>

    <link name="link3_p1">
        <visual>
			<origin xyz="0 0 0" rpy="0 0 0"/>
            <geometry>
                <mesh filename="package://urdf_rozh_v1/meshes/link3_fin.stl" />
            </geometry>
            <!-->material name="gray"/<!-->
        </visual>
        <collision>
			<origin xyz="0 0 0" rpy="0 0 0"/>
            <geometry>
                <mesh filename="package://urdf_rozh_v1/meshes/link3_fin.stl" />
            </geometry>
        </collision>
		<inertial>
			<origin xyz="0 0 0" rpy="0 0 0" />
            <mass value="0.070" />
            <inertia ixx="41" iyy="64" izz="65" ixy="0.0" ixz="1" iyz="0.0" />
        </inertial>
    </link>

    <joint name="joint2_p1" type="continuous">
        <parent link="link1_p1" />
        <child link="link2_p1" />
        <origin rpy="0 0 0" xyz="5.3 -0.12 0" />
        <axis xyz="0 1 0" />
    </joint>
    <joint name="joint3_p1" type="continuous">
        <parent link="link2_p1" />
        <child link="link3_p1" />
        <origin rpy="0 0 3.14159265359" xyz="8.3 0.12 0" />
        <axis xyz="0 1 0" />
    </joint>

    <gazebo>
        <plugin name="gazebo_ros_control" filename="libgazebo_ros_control.so">
            <robotNamespace>/</robotNamespace>
        </plugin>
    </gazebo>
   
</robot>
