<?xml version="1.0"?>
<robot xmlns:xacro="http://www.ros.org/wiki/xacro" name="rozh_model">

	<xacro:macro name="link_model" params="name mass *cad">
		<link name="${name}">
				<visual>
				<geometry>
					<xacro:insert_block name="cad" />
				</geometry>
			<!-->material name="gray"/<!-->
		    </visual>
		    <collision>
				<geometry>
					<xacro:insert_block name="cad" />
				</geometry>
		    </collision>
			<inertial>
				<origin rpy="0 0 0" xyz="0 0 0" />
				<mass value="${mass}" />
				<inertia ixx="0.03" iyy="0.03" izz="0.03" ixy="0.0" ixz="0.0" iyz="0.0" />
			</inertial>
		</link>

	</xacro:macro>

	<xacro:macro name="joints_model" params="name parent child axis *origin">
	    <joint name="${name}" type="continuous">
		    <parent link="${parent}" />
		    <child link="${child}" />
	        <xacro:insert_block name="origin"/>
		    <axis xyz="${axis}" />
		</joint>
    </xacro:macro>

		<xacro:link_model name="prosoma_link" mass="0.1">
		    <mesh filename="package://urdf_rozh_v1/meshes/prosoma_fin.stl"/>
		</xacro:link_model>

	<xacro:macro name="leg_model" params="leg_num *originj1 *originj2 *originj3">

		<xacro:link_model name="link1_p${leg_num}" mass="0.1">
		    <mesh filename="package://urdf_rozh_v1/meshes/link1_fin.stl"/>
		</xacro:link_model>

		<xacro:link_model name="link2_p${leg_num}" mass="0.1">
		    <mesh filename="package://urdf_rozh_v1/meshes/link2_fin.stl"/>
		</xacro:link_model>

		<xacro:link_model name="link3_p${leg_num}" mass="0.1">
		    <mesh filename="package://urdf_rozh_v1/meshes/link3_fin.stl"/>
		</xacro:link_model>

		<xacro:joints_model name="joint1_p${leg_num}" parent="prosoma_link" child="link1_p${leg_num}" axis="0 0 1">
		    <xacro:insert_block name="originj1"/>
		</xacro:joints_model>

		<xacro:joints_model name="joint2_p${leg_num}" parent="link1_p${leg_num}" child="link2_p${leg_num}" axis="0 1 0">
		    <xacro:insert_block name="originj2"/>
		</xacro:joints_model>

		<xacro:joints_model name="joint3_p${leg_num}" parent="link2_p${leg_num}" child="link3_p${leg_num}" axis="0 1 0">
		    <xacro:insert_block name="originj3"/>
		</xacro:joints_model>
	</xacro:macro>

	<xacro:leg_model leg_num="1">
			<origin xyz="6 8.5 0.06" rpy="0 0 0.7854" />
		    <origin xyz="5.3 -0.05 0" rpy="0 0 0" />
		    <origin xyz="8.3 0.05 0" rpy="0 0 3.14159265359" />
	</xacro:leg_model>

	<xacro:leg_model leg_num="2">
		<origin xyz="-6 8.5 0.06" rpy="0 0 2.35619449019" />
		<origin xyz="5.3 -0.05 0" rpy="0 0 0" />
		<origin xyz="8.3 0.05 0" rpy="0 0 3.14159265359" />
	</xacro:leg_model>	

	<xacro:leg_model leg_num="3">
		<origin xyz="-6 -8.5 0.06" rpy="0 0 -2.35619449019" />
		<origin xyz="5.3 -0.05 0" rpy="0 0 0" />
		<origin xyz="8.3 0.05 0" rpy="0 0 3.14159265359" />
	</xacro:leg_model>	

	<xacro:leg_model leg_num="4">
		<origin xyz="6 -8.5 0.06" rpy="0 0 -0.7854" />
	    <origin xyz="5.3 -0.05 0" rpy="0 0 0" />
	    <origin xyz="8.3 0.05 0" rpy="0 0 3.14159265359" />
	</xacro:leg_model>

	<xacro:leg_model leg_num="5">
		<origin xyz="7.125 0 0.06" rpy="0 0 0" />
	    <origin xyz="5.3 -0.05 0" rpy="0 0 0" />
	    <origin xyz="8.3 0.05 0" rpy="0 0 3.14159265359" />
	</xacro:leg_model>

	<xacro:leg_model leg_num="6">
		<origin xyz="-7.125 0 0.06" rpy="0 0 3.14159265359" />
	    <origin xyz="5.3 -0.05 0" rpy="0 0 0" />
	    <origin xyz="8.3 0.05 0" rpy="0 0 3.14159265359" />
	</xacro:leg_model>

    <gazebo>
        <plugin name="gazebo_ros_control" filename="libgazebo_ros_control.so">
            <robotNamespace>/</robotNamespace>
        </plugin>
    </gazebo>

</robot>
    

