<?xml version="1.0" encoding="utf-8" ?>
<!-- =================================================================================== -->
<!-- |    This document was autogenerated by xacro from src/urdf_rozh_v1/urdf/rozh_model.xacro | -->
<!-- |    EDITING THIS FILE BY HAND IS NOT RECOMMENDED                                 | -->
<!-- =================================================================================== -->
<robot name="rozh_model">
    <link name="prosoma_link">
        <visual>
            <geometry>
                <mesh filename="package://urdf_rozh_v1/meshes/prosoma_fin.stl" />
            </geometry>
        </visual>
        <collision>
            <geometry>
                <mesh filename="package://urdf_rozh_v1/meshes/prosoma_collision.stl" />
            </geometry>
        </collision>
        
	    <inertial>
            <mass value="0.533" />
            <inertia ixx="0.001985" iyy="0.001487" izz="0.003307" ixy="0.0" ixz="0.0" iyz="0.0" />
        </inertial>
    </link>

    <link name="link1_p1">
        <visual>
            <geometry>
                <mesh filename="package://urdf_rozh_v1/meshes/link1_fin.stl" />
            </geometry>
        </visual>
        <collision>
            <geometry>
                <mesh filename="package://urdf_rozh_v1/meshes/link1_fin.stl" />
            </geometry>
        </collision>
        
	    <inertial>
            <mass value="0.015" />
            <inertia ixx="0.000005905" iyy="0.00001703" izz="0.00001703" ixy="0.0" ixz="0.0" iyz="0.0" />
        </inertial>
    </link>

    <link name="link2_p1">
        <visual>
            <geometry>
                <mesh filename="package://urdf_rozh_v1/meshes/link2_fin.stl" />
            </geometry>
            <!-->material name="gray"/<!-->
        </visual>
        <collision>
            <geometry>
                <mesh filename="package://urdf_rozh_v1/meshes/link2_collision.stl" />
            </geometry>
        </collision>
		<inertial>
            <mass value="0.112" />
            <inertia ixx="0.00001853" iyy="0.000306" izz="0.0003123" ixy="0.0" ixz="0.0" iyz="0.0" />
        </inertial>
    </link>

    <link name="link3_p1">
        <visual>
            <geometry>
                <mesh filename="package://urdf_rozh_v1/meshes/link3_fin.stl" />
            </geometry>
            <!-->material name="gray"/<!-->
        </visual>
        <collision>
            <geometry>
                <mesh filename="package://urdf_rozh_v1/meshes/link3_fin.stl" />
            </geometry>
        </collision>
		<inertial>
            <mass value="0.070" />
            <inertia ixx="0.000041" iyy="0.000064" izz="0.000065" ixy="0.0" ixz="0.00001" iyz="0.0" />
        </inertial>
    </link>

    <joint name="joint1_p1" type="continuous">
        <parent link="prosoma_link" />
        <child link="link1_p1" />
        <origin rpy="0 0 0.7854" xyz="6 8.5 0.06" />
        <axis xyz="0 0 1" />
    </joint>
    <joint name="joint2_p1" type="continuous">
        <parent link="link1_p1" />
        <child link="link2_p1" />
        <origin rpy="0 0 0" xyz="5.3 -0.05 0" />
        <axis xyz="0 1 0" />
    </joint>
    <joint name="joint3_p1" type="continuous">
        <parent link="link2_p1" />
        <child link="link3_p1" />
        <origin rpy="0 0 3.14159265359" xyz="8.3 0.05 0" />
        <axis xyz="0 1 0" />
    </joint>

    <link name="link1_p2">
        <visual>
            <geometry>
                <mesh filename="package://urdf_rozh_v1/meshes/link1_fin.stl" />
            </geometry>
            <!-->material name="gray"/<!-->
        </visual>
        <collision>
            <geometry>
                <mesh filename="package://urdf_rozh_v1/meshes/link1_fin.stl" />
            </geometry>
        </collision>
	    <inertial>
            <mass value="0.015" />
            <inertia ixx="0.000005905" iyy="0.00001703" izz="0.00001703" ixy="0.0" ixz="0.0" iyz="0.0" />
        </inertial>
    </link>


    <link name="link2_p2">
        <visual>
            <geometry>
                <mesh filename="package://urdf_rozh_v1/meshes/link2_fin.stl" />
            </geometry>
            <!-->material name="gray"/<!-->
        </visual>
        <collision>
            <geometry>
                <mesh filename="package://urdf_rozh_v1/meshes/link2_collision.stl" />
            </geometry>
        </collision>
		<inertial>
            <mass value="0.112" />
            <inertia ixx="0.00001853" iyy="0.000306" izz="0.0003123" ixy="0.0" ixz="0.0" iyz="0.0" />
        </inertial>
    </link>

    <link name="link3_p2">
        <visual>
            <geometry>
                <mesh filename="package://urdf_rozh_v1/meshes/link3_fin.stl" />
            </geometry>
            <!-->material name="gray"/<!-->
        </visual>
        <collision>
            <geometry>
                <mesh filename="package://urdf_rozh_v1/meshes/link3_fin.stl" />
            </geometry>
        </collision>
		<inertial>
            <mass value="0.07" />
            <inertia ixx="0.000041" iyy="0.000064" izz="0.000065" ixy="0.0" ixz="0.00001" iyz="0.0" />
        </inertial>
    </link>

    <joint name="joint1_p2" type="continuous">
        <parent link="prosoma_link" />
        <child link="link1_p2" />
        <origin rpy="0 0 2.35619449019" xyz="-6 8.5 0.06" />
        <axis xyz="0 0 1" />
    </joint>
    <joint name="joint2_p2" type="continuous">
        <parent link="link1_p2" />
        <child link="link2_p2" />
        <origin rpy="0 0 0" xyz="5.3 -0.05 0" />
        <axis xyz="0 1 0" />
    </joint>
    <joint name="joint3_p2" type="continuous">
        <parent link="link2_p2" />
        <child link="link3_p2" />
        <origin rpy="0 0 3.14159265359" xyz="8.3 0.05 0" />
        <axis xyz="0 1 0" />
    </joint>


    <link name="link1_p3">
        <visual>
            <geometry>
                <mesh filename="package://urdf_rozh_v1/meshes/link1_fin.stl" />
            </geometry>
            <!-->material name="gray"/<!-->
        </visual>
        <collision>
            <geometry>
                <mesh filename="package://urdf_rozh_v1/meshes/link1_fin.stl" />
            </geometry>
        </collision>
       
	    <inertial>
            <mass value="0.015" />
            <inertia ixx="0.000005905" iyy="0.00001703" izz="0.00001703" ixy="0.0" ixz="0.0" iyz="0.0" />
        </inertial>
	</link>

    <link name="link2_p3">
        <visual>
            <geometry>
                <mesh filename="package://urdf_rozh_v1/meshes/link2_fin.stl" />
            </geometry>
            <!-->material name="gray"/<!-->
        </visual>
        <collision>
            <geometry>
                <mesh filename="package://urdf_rozh_v1/meshes/link2_collision.stl" />
            </geometry>
        </collision>
		<inertial>
            <mass value="0.112" />
            <inertia ixx="0.00001853" iyy="0.000306" izz="0.0003123" ixy="0.0" ixz="0.0" iyz="0.0" />
        </inertial>
    </link>

    <link name="link3_p3">
        <visual>
            <geometry>
                <mesh filename="package://urdf_rozh_v1/meshes/link3_fin.stl" />
            </geometry>
            <!-->material name="gray"/<!-->
        </visual>
        <collision>
            <geometry>
                <mesh filename="package://urdf_rozh_v1/meshes/link3_fin.stl" />
            </geometry>
        </collision>
		<inertial>
            <mass value="0.07" />
            <inertia ixx="0.000041" iyy="0.000064" izz="0.000065" ixy="0.0" ixz="0.00001" iyz="0.0" />
        </inertial>
    </link>

    <joint name="joint1_p3" type="continuous">
        <parent link="prosoma_link" />
        <child link="link1_p3" />
        <origin rpy="0 0 -2.35619449019" xyz="-6 -8.5 0.06" />
        <axis xyz="0 0 1" />
    </joint>
    <joint name="joint2_p3" type="continuous">
        <parent link="link1_p3" />
        <child link="link2_p3" />
        <origin rpy="0 0 0" xyz="5.3 -0.05 0" />
        <axis xyz="0 1 0" />
    </joint>
    <joint name="joint3_p3" type="continuous">
        <parent link="link2_p3" />
        <child link="link3_p3" />
        <origin rpy="0 0 3.14159265359" xyz="8.3 0.05 0" />
        <axis xyz="0 1 0" />
    </joint>


    <link name="link1_p4">
        <visual>
            <geometry>
                <mesh filename="package://urdf_rozh_v1/meshes/link1_fin.stl" />
            </geometry>
            <!-->material name="gray"/<!-->
        </visual>
        <collision>
            <geometry>
                <mesh filename="package://urdf_rozh_v1/meshes/link1_fin.stl" />
            </geometry>
        </collision>

	    <inertial>
            <mass value="0.015" />
            <inertia ixx="0.000005905" iyy="0.00001703" izz="0.00001703" ixy="0.0" ixz="0.0" iyz="0.0" />
        </inertial>
    </link>

    <link name="link2_p4">
        <visual>
            <geometry>
                <mesh filename="package://urdf_rozh_v1/meshes/link2_fin.stl" />
            </geometry>
            <!-->material name="gray"/<!-->
        </visual>
        <collision>
            <geometry>
                <mesh filename="package://urdf_rozh_v1/meshes/link2_collision.stl" />
            </geometry>
        </collision>
		<inertial>
            <mass value="0.112" />
            <inertia ixx="0.00001853" iyy="0.000306" izz="0.0003123" ixy="0.0" ixz="0.0" iyz="0.0" />
        </inertial>
    </link>

    <link name="link3_p4">
        <visual>
            <geometry>
                <mesh filename="package://urdf_rozh_v1/meshes/link3_fin.stl" />
            </geometry>
            <!-->material name="gray"/<!-->
        </visual>
        <collision>
            <geometry>
                <mesh filename="package://urdf_rozh_v1/meshes/link3_fin.stl" />
            </geometry>
        </collision>
		<inertial>
            <mass value="0.07" />
            <inertia ixx="0.000041" iyy="0.000064" izz="0.000065" ixy="0.0" ixz="0.00001" iyz="0.0" />
        </inertial>
    </link>
    
    <joint name="joint1_p4" type="continuous">
        <parent link="prosoma_link" />
        <child link="link1_p4" />
        <origin rpy="0 0 -0.7854" xyz="6 -8.5 0.06" />
        <axis xyz="0 0 1" />
    </joint>
    <joint name="joint2_p4" type="continuous">
        <parent link="link1_p4" />
        <child link="link2_p4" />
        <origin rpy="0 0 0" xyz="5.3 -0.05 0" />
        <axis xyz="0 1 0" />
    </joint>
    <joint name="joint3_p4" type="continuous">
        <parent link="link2_p4" />
        <child link="link3_p4" />
        <origin rpy="0 0 3.14159265359" xyz="8.3 0.05 0" />
        <axis xyz="0 1 0" />
    </joint>

    <link name="link1_p5">
        <visual>
            <geometry>
                <mesh filename="package://urdf_rozh_v1/meshes/link1_fin.stl" />
            </geometry>
            <!-->material name="gray"/<!-->
        </visual>
        <collision>
            <geometry>
                <mesh filename="package://urdf_rozh_v1/meshes/link1_fin.stl" />
            </geometry>
        </collision>
        
	    <inertial>
            <mass value="0.015" />
            <inertia ixx="0.000005905" iyy="0.00001703" izz="0.00001703" ixy="0.0" ixz="0.0" iyz="0.0" />
        </inertial>
    </link>

    <link name="link2_p5">
        <visual>
            <geometry>
                <mesh filename="package://urdf_rozh_v1/meshes/link2_fin.stl" />
            </geometry>
            <!-->material name="gray"/<!-->
        </visual>
        <collision>
            <geometry>
                <mesh filename="package://urdf_rozh_v1/meshes/link2_collision.stl" />
            </geometry>
        </collision>
		<inertial>
            <mass value="0.112" />
            <inertia ixx="0.00001853" iyy="0.000306" izz="0.0003123" ixy="0.0" ixz="0.0" iyz="0.0" />
        </inertial>
    </link>

    <link name="link3_p5">
        <visual>
            <geometry>
                <mesh filename="package://urdf_rozh_v1/meshes/link3_fin.stl" />
            </geometry>
            <!-->material name="gray"/<!-->
        </visual>
        <collision>
            <geometry>
                <mesh filename="package://urdf_rozh_v1/meshes/link3_fin.stl" />
            </geometry>
        </collision>
		<inertial>
            <mass value="0.07" />
            <inertia ixx="0.000041" iyy="0.000064" izz="0.000065" ixy="0.0" ixz="0.00001" iyz="0.0" />
        </inertial>
    </link>
    
    <joint name="joint1_p5" type="continuous">
        <parent link="prosoma_link" />
        <child link="link1_p5" />
        <origin rpy="0 0 0" xyz="7.125 0 0.06" />
        <axis xyz="0 0 1" />
    </joint>
    <joint name="joint2_p5" type="continuous">
        <parent link="link1_p5" />
        <child link="link2_p5" />
        <origin rpy="0 0 0" xyz="5.3 -0.05 0" />
        <axis xyz="0 1 0" />
    </joint>
    <joint name="joint3_p5" type="continuous">
        <parent link="link2_p5" />
        <child link="link3_p5" />
        <origin rpy="0 0 3.14159265359" xyz="8.3 0.05 0" />
        <axis xyz="0 1 0" />
    </joint>


    <link name="link1_p6">
        <visual>
            <geometry>
                <mesh filename="package://urdf_rozh_v1/meshes/link1_fin.stl" />
            </geometry>
            <!-->material name="gray"/<!-->
        </visual>
        <collision>
            <geometry>
                <mesh filename="package://urdf_rozh_v1/meshes/link1_fin.stl" />
            </geometry>
        </collision>
        
	    <inertial>
            <mass value="0.015" />
            <inertia ixx="0.000005905" iyy="0.00001703" izz="0.00001703" ixy="0.0" ixz="0.0" iyz="0.0" />
        </inertial>
    </link>

    <link name="link2_p6">
        <visual>
            <geometry>
                <mesh filename="package://urdf_rozh_v1/meshes/link2_fin.stl" />
            </geometry>
            <!-->material name="gray"/<!-->
        </visual>
        <collision>
            <geometry>
                <mesh filename="package://urdf_rozh_v1/meshes/link2_collision.stl" />
            </geometry>
        </collision>
		<inertial>
            <mass value="0.112" />
            <inertia ixx="0.00001853" iyy="0.000306" izz="0.0003123" ixy="0.0" ixz="0.0" iyz="0.0" />
        </inertial>
    </link>

    <link name="link3_p6">
        <visual>
            <geometry>
                <mesh filename="package://urdf_rozh_v1/meshes/link3_fin.stl" />
            </geometry>
            <!-->material name="gray"/<!-->
        </visual>
        <collision>
            <geometry>
                <mesh filename="package://urdf_rozh_v1/meshes/link3_fin.stl" />
            </geometry>
        </collision>
		<inertial>
            <mass value="0.070" />
            <inertia ixx="0.000041" iyy="0.000064" izz="0.000065" ixy="0.0" ixz="0.00001" iyz="0.0" />
        </inertial>
    </link>

    <joint name="joint1_p6" type="continuous">
        <parent link="prosoma_link" />
        <child link="link1_p6" />
        <origin rpy="0 0 3.14159265359" xyz="-7.125 0 0.06" />
        <axis xyz="0 0 1" />
    </joint>
    <joint name="joint2_p6" type="continuous">
        <parent link="link1_p6" />
        <child link="link2_p6" />
        <origin rpy="0 0 0" xyz="5.3 -0.05 0" />
        <axis xyz="0 1 0" />
    </joint>
    <joint name="joint3_p6" type="continuous">
        <parent link="link2_p6" />
        <child link="link3_p6" />
        <origin rpy="0 0 3.14159265359" xyz="8.3 0.05 0" />
        <axis xyz="0 1 0" />
    </joint>
   

   <transmission name="trans_joint1_p1">
        <type>transmission_interface/SimpleTransmission</type>
        <joint name="joint1_p1">
            <hardwareInterface>hardware_interface/EffortJointInterface</hardwareInterface>
        </joint>
        <actuator name="joint1_p1_motor">
            <mechanicalReduction>1</mechanicalReduction>
        </actuator>
    </transmission>
    <transmission name="trans_joint2_p1">
        <type>transmission_interface/SimpleTransmission</type>
        <joint name="joint2_p1">
            <hardwareInterface>hardware_interface/EffortJointInterface</hardwareInterface>
        </joint>
        <actuator name="joint2_p1_motor">
            <mechanicalReduction>1</mechanicalReduction>
        </actuator>
    </transmission>
    <transmission name="trans_joint3_p1">
        <type>transmission_interface/SimpleTransmission</type>
        <joint name="joint3_p1">
            <hardwareInterface>hardware_interface/EffortJointInterface</hardwareInterface>
        </joint>
        <actuator name="joint3_p1_motor">
            <mechanicalReduction>1</mechanicalReduction>
        </actuator>
    </transmission>
    <transmission name="trans_joint1_p2">
        <type>transmission_interface/SimpleTransmission</type>
        <joint name="joint1_p2">
            <hardwareInterface>hardware_interface/EffortJointInterface</hardwareInterface>
        </joint>
        <actuator name="joint1_p2_motor">
            <mechanicalReduction>1</mechanicalReduction>
        </actuator>
    </transmission>
    <transmission name="trans_joint2_p2">
        <type>transmission_interface/SimpleTransmission</type>
        <joint name="joint2_p2">
            <hardwareInterface>hardware_interface/EffortJointInterface</hardwareInterface>
        </joint>
        <actuator name="joint2_p2_motor">
            <mechanicalReduction>1</mechanicalReduction>
        </actuator>
    </transmission>
    <transmission name="trans_joint3_p2">
        <type>transmission_interface/SimpleTransmission</type>
        <joint name="joint3_p2">
            <hardwareInterface>hardware_interface/EffortJointInterface</hardwareInterface>
        </joint>
        <actuator name="joint3_p2_motor">
            <mechanicalReduction>1</mechanicalReduction>
        </actuator>
    </transmission>
    <transmission name="trans_joint1_p3">
        <type>transmission_interface/SimpleTransmission</type>
        <joint name="joint1_p3">
            <hardwareInterface>hardware_interface/EffortJointInterface</hardwareInterface>
        </joint>
        <actuator name="joint1_p3_motor">
            <mechanicalReduction>1</mechanicalReduction>
        </actuator>
    </transmission>
    <transmission name="trans_joint2_p3">
        <type>transmission_interface/SimpleTransmission</type>
        <joint name="joint2_p3">
            <hardwareInterface>hardware_interface/EffortJointInterface</hardwareInterface>
        </joint>
        <actuator name="joint2_p3_motor">
            <mechanicalReduction>1</mechanicalReduction>
        </actuator>
    </transmission>
    <transmission name="trans_joint3_p3">
        <type>transmission_interface/SimpleTransmission</type>
        <joint name="joint3_p3">
            <hardwareInterface>hardware_interface/EffortJointInterface</hardwareInterface>
        </joint>
        <actuator name="joint3_p3_motor">
            <mechanicalReduction>1</mechanicalReduction>
        </actuator>
    </transmission>
    <transmission name="trans_joint1_p4">
        <type>transmission_interface/SimpleTransmission</type>
        <joint name="joint1_p4">
            <hardwareInterface>hardware_interface/EffortJointInterface</hardwareInterface>
        </joint>
        <actuator name="joint1_p4_motor">
            <mechanicalReduction>1</mechanicalReduction>
        </actuator>
    </transmission>
    <transmission name="trans_joint2_p4">
        <type>transmission_interface/SimpleTransmission</type>
        <joint name="joint2_p4">
            <hardwareInterface>hardware_interface/EffortJointInterface</hardwareInterface>
        </joint>
        <actuator name="joint2_p4_motor">
            <mechanicalReduction>1</mechanicalReduction>
        </actuator>
    </transmission>
    <transmission name="trans_joint3_p4">
        <type>transmission_interface/SimpleTransmission</type>
        <joint name="joint3_p4">
            <hardwareInterface>hardware_interface/EffortJointInterface</hardwareInterface>
        </joint>
        <actuator name="joint3_p4_motor">
            <mechanicalReduction>1</mechanicalReduction>
        </actuator>
    </transmission>
    <transmission name="trans_joint1_p5">
        <type>transmission_interface/SimpleTransmission</type>
        <joint name="joint1_p5">
            <hardwareInterface>hardware_interface/EffortJointInterface</hardwareInterface>
        </joint>
        <actuator name="joint1_p5_motor">
            <mechanicalReduction>1</mechanicalReduction>
        </actuator>
    </transmission>
    <transmission name="trans_joint2_p5">
        <type>transmission_interface/SimpleTransmission</type>
        <joint name="joint2_p5">
            <hardwareInterface>hardware_interface/EffortJointInterface</hardwareInterface>
        </joint>
        <actuator name="joint2_p5_motor">
            <mechanicalReduction>1</mechanicalReduction>
        </actuator>
    </transmission>
    <transmission name="trans_joint3_p5">
        <type>transmission_interface/SimpleTransmission</type>
        <joint name="joint3_p5">
            <hardwareInterface>hardware_interface/EffortJointInterface</hardwareInterface>
        </joint>
        <actuator name="joint3_p5_motor">
            <mechanicalReduction>1</mechanicalReduction>
        </actuator>
    </transmission>
    <transmission name="trans_joint1_p6">
        <type>transmission_interface/SimpleTransmission</type>
        <joint name="joint1_p6">
            <hardwareInterface>hardware_interface/EffortJointInterface</hardwareInterface>
        </joint>
        <actuator name="joint1_p6_motor">
            <mechanicalReduction>1</mechanicalReduction>
        </actuator>
    </transmission>
    <transmission name="trans_joint2_p6">
        <type>transmission_interface/SimpleTransmission</type>
        <joint name="joint2_p6">
            <hardwareInterface>hardware_interface/EffortJointInterface</hardwareInterface>
        </joint>
        <actuator name="joint2_p6_motor">
            <mechanicalReduction>1</mechanicalReduction>
        </actuator>
    </transmission>
    <transmission name="trans_joint3_p6">
        <type>transmission_interface/SimpleTransmission</type>
        <joint name="joint3_p6">
            <hardwareInterface>hardware_interface/EffortJointInterface</hardwareInterface>
        </joint>
        <actuator name="joint3_p6_motor">
            <mechanicalReduction>1</mechanicalReduction>
        </actuator>
    </transmission>

    <gazebo>
        <plugin name="gazebo_ros_control" filename="libgazebo_ros_control.so">
            <robotNamespace>/</robotNamespace>
        </plugin>
    </gazebo>
   

</robot>
